Workbook

Sheet review 1 - annotator 1 - extrac
A1: |#>
A2: Paper Index | B2: |#>
A3: [54] applsci-09-03723-v2.pdf | B3: Question | C3: What were the machine learning algorithms used in this study? | D3: What features were used to train machine learning models in this study? | E3: Which social network or platform was used for data collection? | F3: What was the size of the analyzed dataset? | G3: What were the performance metrics and their reported values for each machine learning model in the study?
B4: Extracted Context | C4: Furthermore, the classification algorithms like naïve Bayes’, K Nearest Neighbors (KNN), random forest, Support Vector Machine (SVM) and ensemble classification methods (with bagging and boosting)As the second step of our analysis, we apply various machine learning classification models such as SVM, naïve Bayes’, decision tree, KNN and ensemble classification methods with boosting and bagging approaches. Seven diﬀerent classifiers are considered; SVM, naïve Bayes’, decision tree, random forest, KNN, and ensemble methods (with bagging and boosting). The ensemble classification techniques (with bagging and boosting) are applied to build a strong model by combining a set of weak learners to achieve better performance. Naïve Bayes’ 83.16 82.81 80.2 81.48 81.05 79.73 80.84 80.28 68.06 67.87 67.70 67.78 SVM 80.73 80.65 77.21 78.89 84.71 85.18 83.15 84.15 74.10 75.00 73.21 74.09 Decision Tree 76.06 79.56 69.28 74.06 77.43 80.22 71.34 75.52 70.70 76.17 68.77 72.28 Random Forest 70.7 74.04 70.04 71.98 69.56 84.70 50.87 63.56 76.00 78.77 74.69 76.68 KNN 74.78 73.05 72.82 72.93 73.87 70.34 66.29 68.25 72.55 73.85 73.33 73.59 Bagging 83.12 82.21 81.01 81.61 83.66 81.89 80.01 80.94 70.17 73.91 68.44 71.07 Boosting 81.81 80.30 78.56 79.42 84.43 86.29 82.76 84.49 72.52 73.39 71.43 72.40 | D4: In this study we collected data from Twitter using Twitter Streaming API and apply standard preprocessing techniques of NLP that ranges from tokenization, stemming, lemmatization, computing TF-IDF features, etc., to generate a dataset. |#> Sentiment analysis on text usually requires hand written feature derived from word-level (e.g., airstrike, terrorist), word-level n-gram (e.g., doing_good, good_job), character level n-gram (e.g., b, be, beh, av, ave beha, behave), POS tags (e.g., noun, adjective, verb), word cluster (e.g., maybe, probably, prob collapse to the same cluster), hashtag (e.g., #Afghanistan, #Trump), emoticon (e.g., , ), user tags (e.g., @Trump), abbreviations (e.g., WTH, ASAP, ROFL) and elongated words (e.g., yummy, hurrah). Machine learning algorithm needs a numerical picture in the form of a feature vector that enables the model to perform mathematical and statistical investigation. In feature building phase, text data requires to be converted into a manageable representation that is understandable by the algorithm. For this purpose, a feature vector is constructed (i.e., Term Frequency-Inverse Document Frequency) where weighting scheme is applied in order to calculate the score of each token in the corpus. It is defined as: Term Frequency (TF) = frequency of term t in a tweet total terms in tweets (1) total tweets Inverse Document Frequency (IDF) = number of tweets having a term t TF−IDF(t, d) = TF(t, d) ×IDF(t, d) (2) (3) Here, t represents a term in a tweet and d represents a tweet (usually termed as document in text documents). requires to be converted into a manageable representation that is understandable by the algorithm. For this purpose, a feature vector is constructed (i.e., Term Frequency-Inverse Document Frequency) where weighting scheme is applied in order to calculate the score of each token in the corpus. It is defined as: Term Frequency (TF) = frequency of term t in a tweet total terms in tweets (1) total tweets Inverse Document Frequency (IDF) = number of tweets having a term t TF−IDF(t, d) = TF(t, d) ×IDF(t, d) (2) (3) Here, t represents a term in a tweet and d represents a tweet (usually termed as document in text documents). |#>The PCA is considered as a linear method for projecting a high-dimensional dataset onto a low-dimensional space. PCA can also be defined as an orthogonal projection of high-dimensional data to a low-dimensional space in such a way that there will be a maximum variance in the projected data [49–51]. | E4: In this study we collected data from Twitter using Twitter Streaming API and apply standard preprocessing techniques of NLP that ranges from tokenization, stemming, lemmatization, computing TF-IDF features, etc., to generate a dataset. | F4: In order to collect data from Twitter to understand the sentiment of Afghan people after Kunduz Madrassa attack in Afghanistan, the list of query words was prepared based on the trending topics Appl. Sci. 2019, 9, 3723 8 of 21 result of an airstrike conducted by Afghan forces on a religious school in the strong hold area of Taliban on 2 April 2018. Afghan government was of the view that Taliban leaders’ presence at the Madrassa was the reason of this attack by the Afghan forces. Appl. Sci. 2019, 9, 3723 8 of 20 In order to collect data from Twitter to understand the sentiment of Afghan people after Kunduz Madrassa attack in Afghanistan, the list of query words was prepared based on the trending topics on Twitter, from the 2 to 8 April 2018.The total query words that we use for extracting tweets were on Twitter, from the 2 to 8 April 2018. |#> total of 7500 tweets were downloaded based on the the query words in the geo-location of Afghanistan for a span of one week after the Kunduz incident. query words in the geo-location of Afghanistan for a span of one week after the Kunduz incident. All All the collected data were stored locally in an Excel format for further processing and analysis the collected data were stored locally in an Excel format for further processing and analysis purposes. | G4: Classification Algorithms Unigram Bigram Reduced Feature Set (Using PCA) Accuracy Precision Recall F-Score Accuracy Precision Recall F-Score Accuracy Precision Recall F-Score Naïve Bayes’ 83.16 82.81 80.2 81.48 81.05 79.73 80.84 80.28 68.06 67.87 67.70 67.78 SVM 80.73 80.65 77.21 78.89 84.71 85.18 83.15 84.15 74.10 75.00 73.21 74.09 Decision Tree 76.06 79.56 69.28 74.06 77.43 80.22 71.34 75.52 70.70 76.17 68.77 72.28 Random Forest 70.7 74.04 70.04 71.98 69.56 84.70 50.87 63.56 76.00 78.77 74.69 76.68 KNN 74.78 73.05 72.82 72.93 73.87 70.34 66.29 68.25 72.55 73.85 73.33 73.59 Bagging 83.12 82.21 81.01 81.61 83.66 81.89 80.01 80.94 70.17 73.91 68.44 71.07 Boosting 81.81 80.30 78.56 79.42 84.43 86.29 82.76 84.49 72.52 73.39 71.43 72.40
B5: Human Answer | C5: Naive Bayes, SVM, Decision Tree, Random Forest, K-nearest neighbours and ensamble methods (bagging and boosting) | D5: core: TF-IDF |#> possible: Tokenization, Character Transformation, Stop Words Removal, Removing Irregular Terms, Stemming, PCA | E5: Twitter | F5: core: 7500 tweets |#> possible: from 2 to 8 april 2018 | G5: Accuracy, Precision, Recall, F1 Score
B6: Possible Code | C6: AdaBoost, Best-first Search, Char-LSTM, GR-Learnt LSTM, LabelSpreading (RBF), Linear SVC, Logistic Regression, Naive Bayes, Random Forest, Rule-based Classifier, Semi-supervised ML, SVM, SVM-OAA | D6: NA | E6: Articles, Blogs, DWFP, Facebook, Forms, Kaggle, Magazine, News, OSAC, Tumblr, Twitter, WhatsApp, YouTube | F6: NA | G6: Accuracy, F1 Score, MAP, MRR, NDCG, Precision, Recall, ROC-AUC
B7: Human Code (choose from possible_options) | C7: Naive Bayes, SVM, Random Forest, Decision Tree | D7: NA | E7: Twitter | F7: NA
B8: Human Code Proposition for new | C8: K-nearest neighbours, ensamble methods:bagging, ensable methods:boosting | D8: NA | E8: NA | F8: NA
A9: [13] agarwal2014.pdf | B9: Question | C9: What were the machine learning algorithms used in this study? | D9: What features were used to train machine learning models in this study? | E9: Which social network or platform was used for data collection? | F9: What was the size of the analyzed dataset? | G9: What were the performance metrics and their reported values for each machine learning model in the study?
B10: Extracted Context | C10: The research aim of the work presented in this paper is to investigate the application of a focused crawler (best- rst search) based approach for retrieving YouTube user-pro les promoting hate and extremism. |#> BEST-FIRST SEARCHCRAWLER The proposed method is a multi-step process primarily consists of three phases, Training Pro le Collection, Sta tistical Model Building and Focused Crawler. | D10: To investigate the e ec tiveness of contextual features such as the title of the videos uploaded, commented, shared, and favourited for computing the similarity between nodes in the focused crawler traver sal and to examine the e ectiveness of subscribers, featured channels and public contacts as links between nodes. |#> We build our training dataset by extracting the discriminatory features (user ac tivity feeds such as titles of videos uploaded, shared, favour ited & commented by the user and pro le information) of these 35 channels using YouTube API1 |#> BFS method has non-binary priority values assigned to each node. The priority values are the similarity score, which is computed by comparing the users contextual metadata (user activity feeds and pro le information) with training pro les. | E10: Online video sharing platforms such as YouTube contains several videos and users promoting hate and extremism. |#> We collect 35 positive class channels (promoting hate and ex tremism) used as training pro les. We build our training dataset by extracting the discriminatory features (user ac tivity feeds such as titles of videos uploaded, shared, favour ited & commented by the user and pro le information) of these 35 channels using YouTube API | F10: We collect 35 positive class channels (promoting hate and ex tremism) used as training pro les. We build our training dataset by extracting the discriminatory features (user ac tivity feeds such as titles of videos uploaded, shared, favour ited & commented by the user and pro le information) of these 35 channels using YouTube API |#> We create a list of 35 user-ids used as training pro les. The 35 user ids consists of 612 videos and hence the training is performed on 612 videos. |#> we collect results of all 60 iterations and classify 1046 (921 + 125) users as relevant and 381 (314 + 67) as irrelevant users. | G10: Table 1 shows the confusion matrix for binary classi cation performed during Best-First Search approach. Given the input of 10 seed users and 6 modes (pair of threshold and n-gram values) we get di erent number of connected users in each iteration. To measure the accuracy of our proposed approach we collect results of all 60 iterations and classify 1046 (921 + 125) users as relevant and 381 (314 + 67) as irrelevant users. There is a misclassi cation of 2542% and 6510% in predicting the relevant and irrelevant users respectively. |#> Table 1: Best-First Search Confusion Matrix Predicted Relevant Irrelevant Actual Relevant 921 314 Irrelevant 125 67
B11: Human Answer | C11: Best-first Search | D11: video titles, profile info, subscribers, featured channels, contacts | E11: YouTube | F11: 35 channels / 612 videos (train), 10 channels (test), 1,427 users classified. | G11: core: Accuracy = 69.2% |#> possible: TP 921, FN 314, FP 125, TN 67; misclass. 25.42% (relevant), 65.10% (irrelevant).
B12: Possible Code | C12: AdaBoost, Best-first Search, Char-LSTM, GR-Learnt LSTM, LabelSpreading (RBF), Linear SVC, Logistic Regression, Naive Bayes, Random Forest, Rule-based Classifier, Semi-supervised ML, SVM, SVM-OAA | D12: NA | E12: Articles, Blogs, DWFP, Facebook, Forms, Kaggle, Magazine, News, OSAC, Tumblr, Twitter, WhatsApp, YouTube | F12: NA
B13: Human Code (choose from possible_options) | C13: Best-first Search | D13: NA | E13: YouTube | F13: NA
B14: Human Code Proposition for new | C14: NA | D14: NA | E14: NA | F14: NA
A15: [33] 8657a161.pdf | B15: Question | C15: What were the machine learning algorithms used in this study? | D15: What features were used to train machine learning models in this study? | E15: Which social network or platform was used for data collection? | F15: What was the size of the analyzed dataset? | G15: What were the performance metrics and their reported values for each machine learning model in the study?
B16: Extracted Context | C16: We have used three different classification algorithms: SVM, Naive Bayes and Adaboost. | D16: In our experiments we have used three different classes of features: • stylometric features (S) • time based features (T) • sentiment based features (SB) |#> After removing the features that did not effect the classifi cation we used 579 stylometric features, 36 time based features and 4 sentiment based features. | E16: In this work we will focus on Twitter and the distribution of jihadist messages on Twitter.|#> We have collected a set of tweets containing hashtags related to jihadists, and in particular ISIS, from the English language spectrum of pro ISIS clusters on Twitter. | F16: The list we used consisted of 6729 user names. We use only tweets that were posted by these users. Apart from the dataset containing tweets supporting Jihadist groups we also collected 2000 random tweets discussing various topics and a set of tweets that was from accounts that are against ISIS. |#> For the experiments we have used between 4000 and 7500 tweets in total and the ratio between testing data set and training data set was approximately 1:4 | G16: The results from the experiments using the different feature sets are reported using confusion matrices in which we present the number of true positives, false negatives, true negatives, and false positives as illustrated in Table III. Predicted class Actual class True Pos. (TP) False Pos. (FP) False Neg. (FN) True Neg. (TN) TABLE III: Confusion matrix |#> Non Radical Radical Correctly Classified Instances SVM 1974 24 99.1% 11 1990 Naive Bayes 1997 1 99.9% 1 1990 AdaBoost 1998 0 100% 0 1991 TABLE IV: Results when using features (S+T+SB)onthe datasets TW-RAND and TW-PRO.|#> Non Radical Radical Correctly Classified Instances SVM 1155 38 98.5% 24 2783 Naive Bayes 1178 15 96.8% 114 2693 AdaBoost 1182 11 99.5% 8 2799 TABLE V: Results when using all features (S+T+SB)on TW-CON and TW-PRO |#> Non Radical Radical Correctly Classified Instances SVM 3099 92 97.9% 74 4813 Naive Bayes 2877 314 89.0% 574 4313 AdaBoost 1600 0 100% 0 2905 TABLE VI: Results when using all features (S + T + SB) on the full dataset
B17: Human Answer | C17: SVM, Naive Bayes and Adaboost. | D17: Stylometric, time-based, sentiment-based features | E17: Twitter | F17: 6729 user accounts, datasets of pro-ISIS, random (2000), and anti-ISIS tweets; total 4,000–7,500 tweets | G17: SVM 97.9%, NB 89.0%, AdaBoost 100%
B18: Possible Code | C18: AdaBoost, Best-first Search, Char-LSTM, GR-Learnt LSTM, LabelSpreading (RBF), Linear SVC, Logistic Regression, Naive Bayes, Random Forest, Rule-based Classifier, Semi-supervised ML, SVM, SVM-OAA | D18: NA | E18: Articles, Blogs, DWFP, Facebook, Forms, Kaggle, Magazine, News, OSAC, Tumblr, Twitter, WhatsApp, YouTube | F18: NA | G18: NA
B19: Human Code (choose from possible_options) | C19: SVM, Naive Bayes, Adaboost. | D19: NA | E19: Twitter | F19: NA | G19: NA
B20: Human Code Proposition for new | C20: NA | D20: NA | E20: NA | F20: NA | G20: NA
A21: [1] 1605.00659v1.pdf | B21: Question | C21: What were the machine learning algorithms used in this study? | D21: What features were used to train machine learning models in this study? | E21: Which social network or platform was used for data collection? | F21: What was the size of the analyzed dataset? | G21: What were the performance metrics and their reported values for each machine learning model in the study?
B22: Extracted Context | C22: We adopt two off-the-shelf learning models as a proof of concept for the three classification tasks that we will discuss later (see 4): Logistic Regression and Random Forests. Logistic Regression: The first implemented algorithm is a simple Logistic Regression (LR) with LASSO regulariza tion. The advantage of this approach is its scalability, which makes it very effective to (possibly real-time) classification tasks on large datasets. The only parameter to tune is the loss function C. We expect that LR will provide the baseline classification and prediction performance. Random Forests: We also use a state-of-the-art implemen tation of Random Forests (RF) [10]. The vectors fed into the learning models represent each user’s features. Random Forests are trained using 100 estimators and adopting the Gini coefficient to measure the quality of splits. Optimal pa rameters setting is obtained via cross validation (see 3.1.1). Note that the goal of this work is not to provide new machine learning techniques, but to illustrate that existing methods can provide promising results. We also explored additional learning models (e.g., SVM, Stochastic Gradient Descent, etc.), which provide comparable prediction perfor mance but are less computationally efficient and scalable | D22: We manually crafted a set of 52 features belonging to three different classes: user metadata, timing features, and network statistics, as detailed below. User metadata and activity features: User metadata have been proved pivotal to model classes of users in social media [12], [13]. We build user-based features leveraging the metadata provided by the Twitter API related to the author of each tweet, as well as the source of each retweet. User features include the number of tweets, followers and friends associated to each users, the frequency of adoption of hashtags, mentions, and URLs, and finally some profile descriptors. In total, 18 user metadata and activity features are computed (cf. Table 1). |#> TABLE 1. LIST OF 52 FEATURES EXTRACTED BY OUR FRAMEWORK User metadata & activity Number of followers Number of friends (i.e., followees) Number of posted tweets Number of favorite tweets Ratio of retweets / tweets Ratio of mentions / tweets Avg number of hashtags (avg, var) number of retweets Avg. number of mentions Avg. number of mentions (excluding retweets) Number of URLs in profile description (avg, std, min, max, proportion) URLs in tweets Length of username Timing (avg, var) number of tweets per day (avg, std, min, max) interval between two consecutive tweets (avg, std, min, max) interval between two consecutive retweets (avg, std, min, max) interval between two consecutive mentions Netw. stats (avg, std, min, max) distribution of retweeters’ number of followers (avg, std, min, max) distribution of retweeters’ number of friends (avg, std, min, max) distribution of mentioners’ number of followers (avg, std, min, max) distribution of mentioners’ number of friends (avg, std, min, max) number of retweets of the tweets by others |#> Timing features: Important insights may be concealed by the temporal dimension of content production and consump tion, as illustrated by recent work |#> Network statistics: Twitter content spreads from person to person via retweets and mentions. | E22: We tapped into Twitter to obtain a relevant dataset, leveraged expert crowd-sourcing for annotation purposes, and then designed, trained and tested the performance of our prediction system in static and simulated real-time forecasts, as detailed below |#> The next step of our study consisted in collecting data related to the activity of the 25,538 ISIS supporters on Twit ter. |#> | F22: The next step of our study consisted in collecting data related to the activity of the 25,538 ISIS supporters on Twit ter. |#> ISIS accounts: this dataset contains 3,395,901 tweets gen erated in the time interval January-June 2015 by the 25,538 accounts identified by Twitter as supporters of ISIS. This is a significant portion of all the accounts suspended by Twitter in relation to ISIS.1 Users exposed to ISIS: this dataset contains 29,193,267 tweets generated during January-June 2015 by a set of 25 thousand users randomly sampled among the larger set of users that constitute ISIS accounts’ followers. This set is by choice of equal size to the former one, to avoid introducing class imbalance issues. | G22: Table2summarizestheperformanceofLRand RFaccordingtothefourqualitymeasuresdescribedabove (cf.3.1.2):Bothmodelsperformwell,withRandomForests achieving an accuracy above 87%asmeasuredbyAUC. Theseresultsareencouraginganddemonstrate that simple off-the-shelfmodelscanyieldgoodperformanceinT1A. |#> Table4summarizes theperformance ofourmodels:RandomForestsemergesagainas thebest performer, although the gapwith Logistic Regression is narrow, and the latter provides significantlybetterRecall. Overall,T2AappearsclearlymorechallengingthanT1A,as thetopperformanceyieldsa77.1%AUCscore.Theresults onthestaticpredictionarepromisingandsetagoodbaseline for thereal-timepredictionscenario,discussednext.|#> Table6reports the predictionperformanceofour twomodels:overall, thetask proveschallengingasexpected, beingRandomForests the bestperformer, yieldingexcellentRecall and69.2%AUC. LogisticRegressionprovidesfairperformancewitha65.8% AUCscore, andbothPrecisionandRecallaround69%.
B23: Human Answer | C23: Logistic Regression with LASSO regularization and Random Forests | D23: user metadata, timing features, network statistics | E23: Twitter | F23: The dataset included about 3.4 million tweets from 25,538 extremist accounts and about 29 million tweets from 25,000 regular users | G23: The study used Precision, Recall, F1, and AUC as performance metrics. The best AUC scores in real-time predictions with Random Forests were 93.2% for extremist detection, 80.2% for content adoption, and 72.6% for interaction reciprocity.
B24: Possible Code | C24: AdaBoost, Best-first Search, Char-LSTM, GR-Learnt LSTM, LabelSpreading (RBF), Linear SVC, Logistic Regression, Naive Bayes, Random Forest, Rule-based Classifier, Semi-supervised ML, SVM, SVM-OAA | D24: NA | E24: Articles, Blogs, DWFP, Facebook, Forms, Kaggle, Magazine, News, OSAC, Tumblr, Twitter, WhatsApp, YouTube | F24: NA | G24: NA
B25: Human Code (choose from possible_options) | C25: Logistic Regression, Random Forests (RF) | D25: NA | E25: Twitter | F25: NA | G25: NA
B26: Human Code Proposition for new | C26: NA | D26: NA | E26: NA | F26: NA | G26: NA
A27: [20] Thabit-HybridizedTerm-WeightingMethod_Revised_Final_s.pdf | B27: Question | C27: What were the machine learning algorithms used in this study? | D27: What features were used to train machine learning models in this study? | E27: Which social network or platform was used for data collection? | F27: What was the size of the analyzed dataset? | G27: What were the performance metrics and their reported values for each machine learning model in the study?
B28: Extracted Context | C28: Table 3 Classifiers parameters Classifier Parameters SVM KNN Kernel: Linear | default values for other parameters K = 25 | Distance function : Euclidean DT NB ELM Default Default | D28: The next step in the experiment was the representation of the documents in VSM model, based on different term-weighting techniques A, B, C, D, and E, which stands for TF, DF, TF-IDF, Glasgow, and Entropy weighting techniques, respectively. |#> Figure 13 shows the classification performance of the term weighting schemes, where it can be seen that the schemes E and D which stand for Entropy and Glasgow schemes respectively are generally outperforming other schemes in F-measure, and Accuracy, however, TF-IDF scheme performance is the least in the same perspectives. |#> Using the different term-weighting techniques, HTW combines small feature sets generated by the basic TF, DF, IDF, TF-IDF, Glasgow, and Entropy term-weighting techniques into one feature set in different views. | E28: The data on DWFP is collected from 17 Arabic forums, and many other forums in other languages such as English, German, French, and Russian languages |#> OSAC dataset includes 22,429 Arabic text documents collected from many websites, where the documents are distributed into 11 categories (History, Entertainments, Economics, Education & Family, Religious discussions, Heath, Sports, Astronomy, Stories, Low, and Cooking Recipes). |#> A selected balanced dataset downloaded from the DWFP is used in testing, evaluating and benchmarking the proposed method using many common text classifiers. | F28: OSAC dataset includes 22,429 Arabic text documents collected from many websites, |#> The data on DWFP is collected from 17 Arabic forums, and many other forums in other languages such as English, German, French, and Russian languages (Fu et al., 2010). However, this research focuses on Arabic web pages. Therefore, a native Arabic domain expert labeled the web pages manually. |#> The dataset used for the experiments in this research is a balanced dataset, which consists of 1000 documents (50% of the documents are labeled as dark and 50% are non-dark). In the literature, many existing DW detection studies such as (Aknine et al., 2005; Greevy and Smeaton, 2004) use a balanced dataset in which the | G28: Table 7 ANOVA statistical significance test for classification performance between groups Classifier Performance Measure Hybridization Function Hybridization level Mean number of features* SVM KNN DT NB ELM F-measure SD 1 500 80.80 85.65 37.82 7.43 83.42 2 690 90.10 86.48 44.09 1.88 84.76 3 803 92.80 85.68 49.14 6.49 85.44 4 909 92.20 88.94 41.74 11.04 86.97 5 916 90.00 87.89 54.55 15.52 86.47 UN 1 500 80.80 85.65 37.82 7.43 83.42 2 845 92.40 87.04 54.40 8.72 87.72 3 1094 93.80 88.49 46.43 14.27 89.31 4 1283 93.20 90.14 53.28 16.27 89.98 5 1431 93.00 92.25 58.33 18.12 90.43 Accuracy SD 1 500 77.80 83.88 50.00 50.48 81.82 2 690 89.00 85.08 50.00 49.79 83.36 3 803 92.70 83.71 50.00 50.53 84.66 4 909 91.80 88.00 50.00 51.56 86.42 5 916 90.00 87.10 50.00 53.20 86.60 UN 1 500 77.80 83.88 50.00 50.48 81.82 2 845 91.80 84.99 50.00 49.77 87.10 3 1094 93.60 86.78 50.00 50.16 88.96 4 1283 93.00 88.98 50.00 50.60 89.84 5 1431 93.00 91.80 50.00 51.20 90.50
B29: Human Answer | C29: SVM (Support Vector Machine), KNN (K-Nearest Neighbors), DT (Decision Tree), NB (Naive Bayes), ELM (Extreme Learning Machine) | D29: TF, DF, IDF, TF-IDF, Glasgow, and Entropy | E29: DWFP, OSAC | F29: 1000 documents (50% of the documents are labeled as dark and 50% are non-dark) | OSAC dataset includes 22,429 Arabic text documents | G29: SVM (Acc: 93.6%), KNN (Acc: 91,8%), DT (Acc: 50%), NB (Acc: 51.2%), ELM (Acc: 90.5%)
B30: Possible Code | C30: AdaBoost, Best-first Search, Char-LSTM, GR-Learnt LSTM, LabelSpreading (RBF), Linear SVC, Logistic Regression, Naive Bayes, Random Forest, Rule-based Classifier, Semi-supervised ML, SVM, SVM-OAA | D30: NA | E30: Articles, Blogs, DWFP, Facebook, Forms, Kaggle, Magazine, News, OSAC, Tumblr, Twitter, WhatsApp, YouTube | F30: NA | G30: NA
B31: Human Code (choose from possible_options) | C31: SVM, KNN, DT, NB, ELM | D31: NA | E31: DWFP, OSAC | F31: NA | G31: NA
B32: Human Code Proposition for new | C32: ELM (Extreme Learning Machine) | D32: NA | E32: NA | F32: NA | G32: NA
A33: [21] PID5934311.pdf | B33: Question | C33: What were the machine learning algorithms used in this study? | D33: What features were used to train machine learning models in this study? | E33: Which social network or platform was used for data collection? | F33: What was the size of the analyzed dataset? | G33: What were the performance metrics and their reported values for each machine learning model in the study?
B34: Extracted Context | C34: we experimented with multiple classification algorithms, including RF, NN, SVM, and KNN and found that RF and NN produced the best performance. | D34: We explore three categories of information to identify relevant features to detect radical content. Some features are user-based while others are message-based. The three categories are: 1) Radical language (Textual features FT); 2) Psychological sig nals (Psychological features FP); and 3) Behavioural features (FB). | E34: ) we evaluate these models on Twitter to determine the extent to which it is possible to automatically identify online radical tweets. |#> We verify that this dataset is indeed non radical by checking the status of users in Twitter and found that a subset (24000 users) was suspended. We remove those 4https://www.kaggle.com/fifthtribe/how-isis-uses-twitter/data 5https://www.kaggle.com/activegalaxy/isis-related-tweets/home from the dataset and only keep users that are still active on Twitter. This dataset is labelled as counterpoise data.|#> We acquired a publicly available dataset of tweets posted by known pro-ISIS Twitter accounts that was published during the 2015 Paris attacks by Kaggle data science community4. | F34: The dataset consists of around 17000 tweets posted by more than 100 users. |#> This second dataset consists of around 8000 tweets published by around 1000 users. A random sample of 200 tweets was manually verified to ascertain it did not contain radical views. |#> A third dataset is used which was acquired from Kaggle community5. This dataset is created to be a counterpoise to the pro-ISIS dataset (our known-bad) as it consists of tweets talking about topics concerning ISIS without being radical. It contains 122000 tweets from around 95000 users collected on two separate days. | G34: TABLE I: Exp 1: Evaluation metrics across all feature groups Features AC Precision Recall F-measure FT(tf idf) 0.52 0.76 0.52 0.37 FT(w2v) 0.81 0.82 0.81 0.81 FT 0.84 0.84 0.84 0.84 FB 0.94 0.95 0.94 0.94 FP 1.0 1.0 1.0 1.0 FALL 1.0 1.0 1.0 1.0 TABLE II: Exp 2: Evaluation metrics across all feature groups Features AC Precision Recall F-measure FT(tf idf) 0.56 0.69 0.56 0.48 FT(w2v) 0.73 0.73 0.73 0.73 FT 0.80 0.80 0.80 0.80 FB 0.91 0.92 0.91 0.91 FP 1.0 1.0 1.0 1.0 FALL 1.0 1.0 1.0 1.0
B35: Human Answer | C35: Random Forest (RF), Neural Networks (NN), Support Vector Machine (SVM), and K-Nearest Neighbors (KNN). | D35: The models used textual (radical language), psychological signals, and behavioural features. | E35: Twitter | F35: The study analyzed three datasets: 17k tweets (100+ users), 8k tweets (1k users), and 122k tweets (95k users). | G35: The metrics were accuracy, precision, recall, F1, and AUC. Reported values ranged from 0.52 (TF-IDF) up to 1.0 (psychological features FP).
B36: Possible Code | C36: AdaBoost, Best-first Search, Char-LSTM, GR-Learnt LSTM, LabelSpreading (RBF), Linear SVC, Logistic Regression, Naive Bayes, Random Forest, Rule-based Classifier, Semi-supervised ML, SVM, SVM-OAA | D36: NA | E36: Articles, Blogs, DWFP, Facebook, Forms, Kaggle, Magazine, News, OSAC, Tumblr, Twitter, WhatsApp, YouTube | F36: NA | G36: NA
B37: Human Code (choose from possible_options) | C37: RF, NN, SVM, KNN | D37: NA | E37: Twitter | F37: NA | G37: NA
B38: Human Code Proposition for new | C38: NA | D38: NA | E38: NA | F38: NA | G38: NA
A39: [23] 1902.01577v1.pdf | B39: Question | C39: What were the machine learning algorithms used in this study? | D39: What features were used to train machine learning models in this study? | E39: Which social network or platform was used for data collection? | F39: What was the size of the analyzed dataset? | G39: What were the performance metrics and their reported values for each machine learning model in the study?
B40: Extracted Context | C40: Semi-Supervised: Laplacian support vector machines (SVM) [2], graph inference-based label spreading ap proach [21] with radial basis function (RBF) and K-nearest neighbor (KNN) kernels, and co-training learner [7] with two SVMs. Supervised: SVM, KNN, Gaussian na¨ ıve Bayes, lo gistic regression, adaboost, random forest, and Char LSTM [24]. |#> SVM: Tolerance for stopping criteria was set to the default value of 0.001. Penalty parameter C was set to 1 and linear kernel was used. Char-LSTM: This is similar to the character-aware models used for sequential word predictions. We adapt the neural network to a sequence classification problem where the inputs are the vector of one-hot encoding of each character of the handle and the output is the handle being classified as extremist or non-extremist. We set the maximum username length to 10, padding with zeros where necessary. We use an embedding layer after the input layer to convert each username dimension to 16. This is fed to a single layer LSTM module having 30 units. LabelSpreading (RBF): RBF Kernel was used and was set to the default value of 20. Laplacian SVM: We used linear kernel and set the parameters Cl = 06 and Cs = 06. LabelSpreading (KNN): KNN kernel was used and the number of neighbors was set to 5. Co-training (SVM): We followed the algorithm intro duced in [7] and used two SVM as our classifiers. For both SVMs we set the tolerance for stopping criteria to 0.001 and the penalty parameter C = 1. KNN: The number of neighbors was set to 5. Gaussian NB: There were no specific parameter to tune. Logistic regression: We used the l2 penalty. We also set the parameter C = 1 (the inverse of regularization strength) and tolerance for stopping criteria to 0.01. Adaboost: The number of estimators was set to 200 and we also set the learning rate to 0.01. Random forest: We used 200 estimators and the entropy criterion was used. | D40: Twitter handle’s related features: this group contains 3 features related to the given handle, namely, length of the handle, number of unique characters in the handle, and complexity of the handle. To compute the complexity, Kolmogorov complexity is used, which is defined as the length of the shortest program to reproduce the handle on a universal machine such as Turing machine [13]. Since Kolmogorov complexity is computationally in tractable, we use the Entropy of the handle as a way to approximate its complexity. 2) Profile related features: this group contains 7 features related to the profile of the user who posted the tweet, in cluding the number of her followers, friends and tweets, the existence of profile’s description and location. Also, for the last two features in this group, we check if the account is verified and geo-enabled. 3) Content related features: we have the following 3 features related to the content of the given tweet: the number of URLs, the number of hashtags and the sentiment of the content. For the sentiment, we check if the content has a higher negative score than its positive score. | E40: Results on a real-world ISIS-related dataset from Twitter demonstrate the effectiveness of the methodology in identifying extremist users. |#> The dataset was collected from Twitter and consists of ap proximately 1.6M tweets that were posted using 25 extremism related hashtags such as #AbuBakralBaghdadi, #ISIL, #ISIS, #Daesh, and #IslamicState. | F40: The dataset was collected from Twitter and consists of ap proximately 1.6M tweets that were posted using 25 extremism related hashtags such as #AbuBakralBaghdadi, #ISIL, #ISIS, #Daesh, and #IslamicState. |#> We construct our extremist labels (positive labels) by collecting a limited number of 150 suspended ISIS-related Twitter handles which were reported to the Twitter Safety account (@TwitterSafety) by normal users. To make a balanced labeled dataset, 150 random handles corresponding to normal users were also collected to serve as our negative labels. |#> This way, we obtain 300K highly extremism related tweets from which we randomly pick a smaller sample of 3K handles who posted the tweets. | G40: we report the average of 10 different runs, using various evaluation metrics including precision, recall and F1-score in Table II. |#> TABLE II COMPARISON OF THE METHODS ON THE LABELED DATA, FOR THE POSITIVE (EXTREMIST) CLASS. Learner Precision Recall F1-score SVM 0.96 0.5 0.65 Char-LSTM 0.77 0.76 0.76 LabelSpreading (RBF) 0.85 0.69 0.76 Laplacian SVM 0.89 0.6 0.7 LabelSpreading (KNN) 0.83 0.67 0.73 Co-Training (SVM) 0.9 0.53 0.66 KNN 0.81 0.7 0.74 Gaussian NB 0.89 0.56 0.69 Logistic Regression 0.76 0.61 0.67 AdaBoost 0.88 0.58 0.69 Random Forest 0.79 0.71 0.74
...

Sheet review 1 - annotator 2 - extrac
A1: |#>
A2: Paper Index
A3: [54] applsci-09-03723-v2.pdf | B3: Question | C3: What were the machine learning algorithms used in this study? | D3: What features were used to train machine learning models in this study? | E3: Which social network or platform was used for data collection? | F3: What was the size of the analyzed dataset? | G3: What were the performance metrics and their reported values for each machine learning model in the study?
B4: Extracted Context | C4: Furthermore, the classification algorithms like naïve Bayes’, K Nearest Neighbors (KNN), random forest, Support Vector Machine (SVM) and ensemble classification methods (with bagging and boosting)As the second step of our analysis, we apply various machine learning classification models such as SVM, naïve Bayes’, decision tree, KNN and ensemble classification methods with boosting and bagging approaches. Seven diﬀerent classifiers are considered; SVM, naïve Bayes’, decision tree, random forest, KNN, and ensemble methods (with bagging and boosting). The ensemble classification techniques (with bagging and boosting) are applied to build a strong model by combining a set of weak learners to achieve better performance. Naïve Bayes’ 83.16 82.81 80.2 81.48 81.05 79.73 80.84 80.28 68.06 67.87 67.70 67.78 SVM 80.73 80.65 77.21 78.89 84.71 85.18 83.15 84.15 74.10 75.00 73.21 74.09 Decision Tree 76.06 79.56 69.28 74.06 77.43 80.22 71.34 75.52 70.70 76.17 68.77 72.28 Random Forest 70.7 74.04 70.04 71.98 69.56 84.70 50.87 63.56 76.00 78.77 74.69 76.68 KNN 74.78 73.05 72.82 72.93 73.87 70.34 66.29 68.25 72.55 73.85 73.33 73.59 Bagging 83.12 82.21 81.01 81.61 83.66 81.89 80.01 80.94 70.17 73.91 68.44 71.07 Boosting 81.81 80.30 78.56 79.42 84.43 86.29 82.76 84.49 72.52 73.39 71.43 72.40 | D4: In this study we collected data from Twitter using Twitter Streaming API and apply standard preprocessing techniques of NLP that ranges from tokenization, stemming, lemmatization, computing TF-IDF features, etc., to generate a dataset. |#> Sentiment analysis on text usually requires hand written feature derived from word-level (e.g., airstrike, terrorist), word-level n-gram (e.g., doing_good, good_job), character level n-gram (e.g., b, be, beh, av, ave beha, behave), POS tags (e.g., noun, adjective, verb), word cluster (e.g., maybe, probably, prob collapse to the same cluster), hashtag (e.g., #Afghanistan, #Trump), emoticon (e.g., , ), user tags (e.g., @Trump), abbreviations (e.g., WTH, ASAP, ROFL) and elongated words (e.g., yummy, hurrah). Machine learning algorithm needs a numerical picture in the form of a feature vector that enables the model to perform mathematical and statistical investigation. In feature building phase, text data requires to be converted into a manageable representation that is understandable by the algorithm. For this purpose, a feature vector is constructed (i.e., Term Frequency-Inverse Document Frequency) where weighting scheme is applied in order to calculate the score of each token in the corpus. It is defined as: Term Frequency (TF) = frequency of term t in a tweet total terms in tweets (1) total tweets Inverse Document Frequency (IDF) = number of tweets having a term t TF−IDF(t, d) = TF(t, d) ×IDF(t, d) (2) (3) Here, t represents a term in a tweet and d represents a tweet (usually termed as document in text documents). requires to be converted into a manageable representation that is understandable by the algorithm. For this purpose, a feature vector is constructed (i.e., Term Frequency-Inverse Document Frequency) where weighting scheme is applied in order to calculate the score of each token in the corpus. It is defined as: Term Frequency (TF) = frequency of term t in a tweet total terms in tweets (1) total tweets Inverse Document Frequency (IDF) = number of tweets having a term t TF−IDF(t, d) = TF(t, d) ×IDF(t, d) (2) (3) Here, t represents a term in a tweet and d represents a tweet (usually termed as document in text documents). |#>The PCA is considered as a linear method for projecting a high-dimensional dataset onto a low-dimensional space. PCA can also be defined as an orthogonal projection of high-dimensional data to a low-dimensional space in such a way that there will be a maximum variance in the projected data [49–51]. | E4: In this study we collected data from Twitter using Twitter Streaming API and apply standard preprocessing techniques of NLP that ranges from tokenization, stemming, lemmatization, computing TF-IDF features, etc., to generate a dataset. | F4: In order to collect data from Twitter to understand the sentiment of Afghan people after Kunduz Madrassa attack in Afghanistan, the list of query words was prepared based on the trending topics Appl. Sci. 2019, 9, 3723 8 of 21 result of an airstrike conducted by Afghan forces on a religious school in the strong hold area of Taliban on 2 April 2018. Afghan government was of the view that Taliban leaders’ presence at the Madrassa was the reason of this attack by the Afghan forces. Appl. Sci. 2019, 9, 3723 8 of 20 In order to collect data from Twitter to understand the sentiment of Afghan people after Kunduz Madrassa attack in Afghanistan, the list of query words was prepared based on the trending topics on Twitter, from the 2 to 8 April 2018.The total query words that we use for extracting tweets were on Twitter, from the 2 to 8 April 2018. |#> total of 7500 tweets were downloaded based on the the query words in the geo-location of Afghanistan for a span of one week after the Kunduz incident. query words in the geo-location of Afghanistan for a span of one week after the Kunduz incident. All All the collected data were stored locally in an Excel format for further processing and analysis the collected data were stored locally in an Excel format for further processing and analysis purposes. | G4: Classification Algorithms Unigram Bigram Reduced Feature Set (Using PCA) Accuracy Precision Recall F-Score Accuracy Precision Recall F-Score Accuracy Precision Recall F-Score Naïve Bayes’ 83.16 82.81 80.2 81.48 81.05 79.73 80.84 80.28 68.06 67.87 67.70 67.78 SVM 80.73 80.65 77.21 78.89 84.71 85.18 83.15 84.15 74.10 75.00 73.21 74.09 Decision Tree 76.06 79.56 69.28 74.06 77.43 80.22 71.34 75.52 70.70 76.17 68.77 72.28 Random Forest 70.7 74.04 70.04 71.98 69.56 84.70 50.87 63.56 76.00 78.77 74.69 76.68 KNN 74.78 73.05 72.82 72.93 73.87 70.34 66.29 68.25 72.55 73.85 73.33 73.59 Bagging 83.12 82.21 81.01 81.61 83.66 81.89 80.01 80.94 70.17 73.91 68.44 71.07 Boosting 81.81 80.30 78.56 79.42 84.43 86.29 82.76 84.49 72.52 73.39 71.43 72.40
B5: Human Answer | C5: Naive Bayes, SVM, Decision Tree, Random Forest, K-nearest neighbours and ensamble methods (bagging and boosting) | D5: core: TF-IDF |#> possible: Tokenization, Character Transformation, Stop Words Removal, Removing Irregular Terms, Stemming, PCA | E5: Twitter | F5: core: 7500 tweets |#> possible: from 2 to 8 april 2018 | G5: Accuracy, Precision, Recall, F1 Score
B6: Possible Code | C6: AdaBoost, Best-first Search, Char-LSTM, Decision Trees, LabelSpreading (RBF), Naive Bayes, Neural Networks, RF, SVM | D6: NA | E6: DWFP, Facebook, Instagram, LinkedIn, OSAC, Reddit, Tumblr, Twitter, YouTube | F6: NA | G6: Accuracy, F1 Score, MAP, MRR, NDCG, Precision, Recall, ROC-AUC
B7: Human Code (choose from possible_options) | C7: Naive Bayes, SVM, Random Forest, Decision Tree | D7: NA | E7: Twitter | F7: NA
B8: Human Code Proposition for new | C8: K-nearest neighbours, ensamble methods:bagging, ensable methods:boosting | D8: NA | E8: NA | F8: NA
A9: [20] Thabit-HybridizedTerm-WeightingMethod_Revised_Final_s.pdf | B9: Question | C9: What were the machine learning algorithms used in this study? | D9: What features were used to train machine learning models in this study? | E9: Which social network or platform was used for data collection? | F9: What was the size of the analyzed dataset? | G9: What were the performance metrics and their reported values for each machine learning model in the study?
B10: Extracted Context | C10: Table 3 Classifiers parameters Classifier Parameters SVM KNN Kernel: Linear | default values for other parameters K = 25 | Distance function : Euclidean DT Default NB Default ELM Default | D10: However, this research considers five weighting schemes to be applied and combined as a hybridized feature selection method. (...) Term frequency (TF), Document frequency (DF), Term frequency - Inverse document frequency (TF-IDF), Glasgow, Entropy | E10: To test and evaluate the HTW method, an experiment was conducted. First, thousands of Arabic web pages were downloaded from the DWFP. DWFP is the largest collection of crawled terrorist-related documents (Fu et al., 2010). The data on DWFP is collected from 17 Arabic forums, and many other forums in other languages such as English, German, French, and Russian languages (Fu et al., 2010) Then non-dark files were added from the Open Source Arabic Corpora (OSAC) (Saad and Ashour, 2010). OSAC dataset includes 22,429 Arabic text documents collected from many websites, where the documents are distributed into 11 categories (History, Entertainments, Economics, Education & Family, Religious discussions, Heath, Sports, Astronomy, Stories, Low, and Cooking Recipes | F10: First, thousands of Arabic web pages were downloaded from the DWFP. The dataset used for the experiments in this research is a balanced dataset, which consists of 1000 documents (50% of the documents are labeled as dark and 50% are non-dark). | G10: 𝐴𝑐𝑐𝑢𝑟𝑎𝑐𝑦 = |𝑇𝑃|+|𝑇𝑁| |𝑇𝑃|+|𝐹𝑃|+|𝐹𝑁|+|𝑇𝑁| o 𝑃𝑟𝑒𝑐𝑖𝑠𝑖𝑜𝑛(𝐷𝑎𝑟𝑘) = |𝑇𝑃| o 𝑅𝑒𝑐𝑎𝑙𝑙(𝐷𝑎𝑟𝑘) = |𝑇𝑃| Authors' copy False Negative (FN): Number of non-dark documents incorrectly identified by the classifier. |𝑇𝑃|+|𝐹𝑃| |𝑇𝑃|+|𝐹𝑁| o 𝐹 − 𝑚𝑒𝑎𝑠𝑢𝑟𝑒 = 2 × 𝑃𝑟𝑒𝑐𝑖𝑠𝑖𝑜𝑛×𝑅𝑒𝑐𝑎𝑙
B11: Human Answer | C11: SVM, KNN, DT, Naive bayes, extreme learning machine | D11: TF-IDF, Glasgow, Entropy | E11: NOT social media, but DWFP and OSAC datasets | F11: thousands of Arabic web pages, final data 1000 documents (50% dark 50% non dark) | G11: f-measure, recall, precision, accurayc
B12: Possible Code | C12: AdaBoost, Best-first Search, Char-LSTM, GR-Learnt LSTM, LabelSpreading (RBF), Linear SVC, Logistic Regression, Naive Bayes, Random Forest, Rule-based Classifier, Semi-supervised ML, SVM, SVM-OAA | D12: NA | E12: DWFP, Facebook, Instagram, LinkedIn, OSAC, Reddit, Tumblr, Twitter, YouTube | F12: NA | G12: Accuracy, F1 Score, MAP, MRR, NDCG, Precision, Recall, ROC-AUC
B13: Human Code (choose from possible_options) | C13: SVM, Naive Bayes | D13: NA | E13: DFWP, OSAC | F13: NA | G13: Accuracy, Recall, F1 Score, Precision
B14: Human Code Proposition for new | C14: Decision Tree, K-neighrest neighbours, extreme learning machine | D14: NA | E14: not social media | F14: NA | G14: NA
A15: [23] 1902.01577v1.pdf | B15: Question | C15: What were the machine learning algorithms used in this study? | D15: What features were used to train machine learning models in this study? | E15: Which social network or platform was used for data collection? | F15: What was the size of the analyzed dataset? | G15: What were the performance metrics and their reported values for each machine learning model in the study?
B16: Extracted Context | C16: Semi-Supervised: Laplacian support vector machines (SVM) [2], graph inference-based label spreading ap- proach [21] with radial basis function (RBF) and K-nearest neighbor (KNN) kernels, and co-training learner [7] with two SVMs. • Supervised: SVM, KNN, Gaussian na¨ ıve Bayes, lo- gistic regression, adaboost, random forest, and Char- LSTM [24]. | D16: 1) Twitter handle’s related features: this group contains 3 features related to the given handle, namely, length of the handle, number of unique characters in the handle, and complexity of the handle. To compute the complexity, Kolmogorov complexity is used, which is defined as the length of the shortest program to reproduce the handle on a universal machine such as Turing machine [13]. Since Kolmogorov complexity is computationally in- tractable, we use the Entropy of the handle as a way to approximate its complexity. 2) Profile related features: this group contains 7 features related to the profile of the user who posted the tweet, in- cluding the number of her followers, friends and tweets, the existence of profile’s description and location. Also, for the last two features in this group, we check if the account is verified and geo-enabled. 3) Content related features: we have the following 3 features related to the content of the given tweet: the number of URLs, the number of hashtags and the sentiment of the content. For the sentiment, we check if the content has a higher negative score than its positive score. | E16: The dataset was collected from Twitter and consists of ap- proximately 1.6M tweets that were posted using 25 extremism- related hashtags such as #AbuBakralBaghdadi, #ISIL, #ISIS, #Daesh, and #IslamicState. We construct our extremist labels (positive labels) by collecting a limited number of 150 suspended ISIS-related Twitter handles which were reported to the Twitter Safety accoun | F16: The dataset was collected from Twitter and consists of ap- proximately 1.6M tweets that were posted using 25 extremism- related hashtags such as #AbuBakralBaghdadi, #ISIL, #ISIS, #Daesh, and #IslamicState. We construct our extremist labels (positive labels) by collecting a limited number of 150 suspended ISIS-related Twitter handles which were reported to the Twitter Safety account (@TwitterSafety) by normal users. To make a balanced labeled dataset, 150 random handles corresponding to normal users were also collected to serve as our negative labels. nspired by the literature [8], [11], [19], we define 3 major groups of overall 13 features, which could be leveraged to filter out less likely extremists. This way, we obtain 300K highly extremism related tweets from which we randomly pick a smaller sample of 3K handles who posted the tweets. Name Value Raw 1.6M Filtered 300K Unlabeled (sampled) 3K Labeled Positive Negative 150 150 | G16: Learner Precision Recall F1-score SVM 0.96 0.5 0.65 Char-LSTM 0.77 0.76 0.76 LabelSpreading (RBF) 0.85 0.69 0.76 Laplacian SVM 0.89 0.6 0.7 LabelSpreading (KNN) 0.83 0.67 0.73 Co-Training (SVM) 0.9 0.53 0.66 KNN 0.81 0.7 0.74 Gaussian NB 0.89 0.56 0.69 Logistic Regression 0.76 0.61 0.67 AdaBoost 0.88 0.58 0.69 Random Forest 0.79 0.71 0.74
B17: Human Answer | C17: SVM, Char-LSTM, LabelSpeading (RBF), Laplacian SVM, LabelSpreading (KNN), Co-Training (SVM), KNN, Gaussian NB, Logistic Regression, AdaBoost, Random Forest | D17: twitter handles related features, profile related features, content related features | E17: Twitter | F17: Original dataset was approximately 1.6M tweets, after filtering it was 300K, sampled 3K | G17: Learner Precision Recall F1-score SVM 0.96 0.5 0.65 Char-LSTM 0.77 0.76 0.76 LabelSpreading (RBF) 0.85 0.69 0.76 Laplacian SVM 0.89 0.6 0.7 LabelSpreading (KNN) 0.83 0.67 0.73 Co-Training (SVM) 0.9 0.53 0.66 KNN 0.81 0.7 0.74 Gaussian NB 0.89 0.56 0.69 Logistic Regression 0.76 0.61 0.67 AdaBoost 0.88 0.58 0.69 Random Forest 0.79 0.71 0.74
B18: Possible Code | C18: AdaBoost, Best-first Search, Char-LSTM, Decision Trees, LabelSpreading (RBF), Naive Bayes, Neural Networks, RF, SVM | D18: NA | E18: DWFP, Facebook, Instagram, LinkedIn, OSAC, Reddit, Tumblr, Twitter, YouTube | F18: NA | G18: Accuracy, Precision, Recall, F1 Score
B19: Human Code (choose from possible_options) | C19: Char-LSTM, SVM, LabelSpreading (RBF), Laplacian SVM, Co-Training SVM, Naive Bayes, Random Forest | D19: NA | E19: Twitter | F19: NA | G19: Precision, Recall F1-score
B20: Human Code Proposition for new | C20: LabelSpreading (KNN) | D20: NA | E20: NA | F20: NA | G20: NA
A21: [34] Detecting-multipliers-of-jihadism_FOI-S--5656--SE.pdf | B21: Question | C21: What were the machine learning algorithms used in this study? | D21: What features were used to train machine learning models in this study? | E21: Which social network or platform was used for data collection? | F21: What was the size of the analyzed dataset? | G21: What were the performance metrics and their reported values for each machine learning model in the study?
B22: Extracted Context | C22: In our experiments we have used an AdaBoost classifier. | D22: Feature class Description Number of features Word length Letters* Digits Punctuation Arabic Function words English Function words Time Emotion words Hashtag * Only for English tweets Relative frequency of words with 1-20 characters Relative frequency of a to z (ignoring case) Relative frequency of 0 to 9 Relative frequency of characters . ? ! , ; : ( ) ” - ´ Relative frequency of various function words Relative frequency of various function words Features related to time Relative frequency of various sentiments words Relative frequency of hashtags 1 TABLE I. DATA INDEPENDENT FEATURES 20 26 10 11 160 293 39 108 Feature class Description Top 10 English features Hashtags Word bigrams Letter bigrams Frequent words 100 most common hashtags 100 most common word bigrams 100 most common word bigrams 100 words that are used most frequently #is, #iraq #islamic state, #alleyesonisis, #syria, #islamicstate, #khilafarestored, #islam, #isis, #muslims of the, islamic state, to the, the islamic, in the, from the, for the, by the, on the, islamic states th, he, in, er, an, is, re, st, es, at the, of, in, to, and, a, from, is, for, islamic The data dependent feature classes that we use are the most common hashtags, most common word bigrams, most common letter bigrams and the most frequent words. | E22: Our approach towards this problem is to use machine learning and train a model that can recognize if a twitter user is supporting a jihadist groups and disseminate propaganda content online (also called a media mujahid). | F22: Our approach towards this problem is to use machine learning and train a model that can recognize if a twitter user is supporting a jihadist groups and disseminate propaganda content online (also called a media mujahid). Dataset Description Size Training Testing Validation TWEEP-PRO-E English tweeps involved in media mujahideen. 93 41 31 21 TWEEP-RAND-E Randomly collected tweeps on English. 742 377 220 145 TWEEP-PRO-A Arabic tweeps involved in media mujahideen. 81 33 28 20 TWEEP-RAND-A Randomly collected tweeps on arabic. 256 136 74 46 TW-PRO-E English tweets containing jihadist propaganda 27753 13994 18027 5459 based on hashtags and network of known jihadists. TW-RAND-E Randomly collected tweets discussing various topics on English. 60000 29882 8299 12091 TW-PRO-A Arabic tweets containing jihadist propaganda. 16000 7973 4836 3191 based on hashtags and network of known jihadists. TW-RAND-A Randomly collected tweets discussing various topics on arabic. 45013 22534 13468 9011 one on English called TW- PRO-E and one on Arabic called TW-PRO-A. We also have two sets of ”random” tweets one English called TW-RAND-E and one on Arabic called TW-RAND-A. | G22: TABLE V. RESULTS FOR CLASSIFYING ARABIC TWEEPS Features Confusion Matrix Precision Accuracy Recall Data independent 45 4 1 16 0.8 0.9242 0.9411 Data dependent 46 1 0 19 0.8260 0.9848 1.0 Data dependent + Data independent 46 2 0 18 0.9 0.9697 1.0 TABLE VI. RESULTS FOR CLASSIFYING ENGLISH TWEEPS Features Data independent Data dependent Data dependent + Data independent Confusion Matrix 145 1 0 20 145 0 0 21 145 0 0 21 Precision 0.9528 1.0 1.0 Accuracy 0.994 1.0 1.0 Recall 1.0 1.0 1.0 TABLE VII. RESULTS FOR CLASSIFYING ARABIC TWEETS Features Data independent Data dependent Data dependent + Data independent Confusion Matrix 8542 1679 469 1512 8699 1560 312 1631 8724 1375 287 1816 Precision 0.4738 0.5111 0.5691 Accuracy 0.824 0.8466 0.8638 Recall 0.7633 0.8394 0.8635 TABLE VIII. RESULTS FOR CLASSIFYING ENGLISH TWEETS Features Data independent Data dependent Data dependent + Data independent Confusion Matrix Precision 12006 122 85 5337 0.9776 12087 159 4 5300 0.9708 12085 80 6 5379 0.9853 Accuracy 0.9882 0.9907 0.9951 Recall 0.9843 0.9992 0.9988
B23: Human Answer | C23: AdaBoost | D23: data independent features such as: word lenght, letters, digits, punctuation, arabic function words, english function words, time, emotion words, hashtag, word bigrams, letter bigrams, frequent words and data dependent features such as most common hashtags, most common word bigrams, most common letter bigrams and most frequent words | E23: twitter | F23: 6729 usernames of known jihadist was used to filter to ensure relevance, of tweets, in total 30 tweeps from twitter guide and 45 tweeps from multipliers of jihadist and latest 3400 tweets were downloaded from each | G23: Precision, Accuracy, Recall
B24: Possible Code | C24: AdaBoost, Best-first Search, Char-LSTM, GR-Learnt LSTM, LabelSpreading (RBF), Linear SVC, Logistic Regression, Naive Bayes, Random Forest, Rule-based Classifier, Semi-supervised ML, SVM, SVM-OAA | D24: NA | E24: DWFP, Facebook, Instagram, LinkedIn, OSAC, Reddit, Tumblr, Twitter, YouTube | F24: NA | G24: Accuracy, F1 Score, MAP, MRR, NDCG, Precision, Recall, ROC-AUC
B25: Human Code (choose from possible_options) | C25: AdaBoost | D25: NA | E25: Twitter | F25: NA | G25: Precision, Accuracy, Recall
B26: Human Code Proposition for new | C26: NA | D26: NA | E26: NA | F26: NA | G26: NA
A27: [35] ICDCIT2015.pdf | B27: Question | C27: What were the machine learning algorithms used in this study? | D27: What features were used to train machine learning models in this study? | E27: Which social network or platform was used for data collection? | F27: What was the size of the analyzed dataset? | G27: What were the performance metrics and their reported values for each machine learning model in the study?
B28: Extracted Context | C28: We employ a single-class SVM and KNN algorithm for one-class classification task. | D28: To identify linguistic and stylistic features and characteristics of hate and extremism promoting tweets. In phase 4, we perform characterization and identification of various discriminatory features and compute the frequency (TF) of various terms. For example, religious, oﬀensive, slang, negative emotions, punctuations and war related terms | E28: We conduct experiments on publicly available dataset so that our results can be replicated or used for benchmarking or comparison purposes. We download two datasets: UDI-TwitterCrawl-Aug20127 and ATM-TwitterCrawl-Aug20138. UDI- TwitterCrawl-Aug2012 consists of 50 million tweets approximately and was col- lected in May 2011 [6]. ATM-TwitterCrawl-Aug2013 consists of 5 million English tweets and was collected in June 2011 [5]. | F28: nitially we have 53, 234, 567 tweets in our dataset. In this paper, we focus only on English language tweets, there- fore we discard all non-English (7, 889, 609) tweets and remain with a total of 45, 344, 958 tweets. To avoid overfitting in classification we collect only 10, 486 labeled tweets for training dataset, which is a very small fraction of experimental dataset. We perform a random sampling on all 45.3 million tweets of experimental dataset and collect a random sample of 1 million tweets as testing (or validation) dataset | G28: Experimental results on large and real-world dataset demonstrate that the proposed approach is eﬀective with F-score of 0.60 and 0.83 for the KNN and SVM classifier respectively. Classifier Precision Recall TNR NPV F-Score Accuracy KNN 0.48 0.81 0.92 0.98 0.60 0.90 LibSVM 0.78 0.88 0.98 0.99 0.83 0.97
